Workbook
Name abc: '4.Excel Ranges'!$G$6:$J$6
Name NativeTimeline_Admission_Date: #N/A
Name range_new: '4.Excel Ranges'!$C$89:$D$89
Name range1: '4.Excel Ranges'!$C$86:$E$86
Name range2: '4.Excel Ranges'!$C$87:$E$87
Name Slicer_BRANCH: #N/A
Name Slicer_BRANCH1: #N/A
Name Slicer_Category: #N/A
Name Slicer_City: #N/A
Name Slicer_City1: #N/A
Name Slicer_Course: #N/A
Name Slicer_PAYMENT_DONE: #N/A
Name Slicer_Payment_Status: #N/A
Name Slicer_Payment_Status1: #N/A
Name Slicer_Property_Name: #N/A
Name Slicer_Region: #N/A
Name tyu: '4.Excel Ranges'!$G$8:$I$8
Name xyz: '4.Excel Ranges'!$A$1:$C$8

Sheet 1.Excel Overview
V1: 46080
H3: workbook
B5: Quick Access bar tool
B7: tabs
B8: Ribbon
Q9: Groups(Each group having properties)
B10: Name Box | Q10: formula bar
Q13: 1. Shape->Shape outline->Weight
Q14: 2. format painter -> as it is format print from 1 cell to another
B24: Right Click ->Rename

Sheet 2.Attendance Sheet2
S2: 46080
B5: Student Name
A6: SR NO | B6: Topic | C6: 1 | D6: 2 | E6: 3 | F6: 4 | G6: 5 | H6: 6 | I6: 7 | J6: 8 | K6: 9 | L6: 10
A7: 1 | B7: Module 1: Introduction to execl | C7: Sign | E7: Sign | H7: Sign | K7: Sign
A8: 2 | B8: Module 1: Introduction to execlModule 1: Introduction to execl | C8: Sign | E8: Sign | H8: Sign | K8: Sign
A9: 3 | B9: Module 1: Introduction to execl | C9: Sign | E9: Sign | H9: Sign | K9: Sign
A10: 4 | B10: Module 1: Introduction to execlModule 1: Introduction to execl | C10: Sign | E10: Sign | H10: Sign | K10: Sign
A11: 5 | B11: Module 1: Introduction to execl | C11: Sign | E11: Sign | H11: Sign | K11: Sign
A12: 6 | B12: Module 1: Introduction to execlModule 1: Introduction to execl | C12: Sign | E12: Sign | H12: Sign | K12: Sign
A13: 7 | B13: Module 1: Introduction to execl | C13: Sign | E13: Sign | H13: Sign | K13: Sign
A14: 8 | B14: Module 1: Introduction to execl | C14: Sign | E14: Sign | H14: Sign | K14: Sign
A15: 9 | B15: Module 1: Introduction to execl | C15: Sign | E15: Sign | H15: Sign | K15: Sign
A16: 10 | B16: Module 1: Introduction to execlModule 1: Introduction to execl | C16: Sign | E16: Sign | H16: Sign | K16: Sign
N18: Steps:
N19: 1. Page Layout->size
N20: 2. Select orientation

Sheet 3.Excel Syntax
A1: 52 | S1: 46081
B3: 60 | D3: =A1+B3+A4 -> 147
A4: 35
A6: ADD:
A7: 23
B8: 44
C9: 445 | F9: Steps:
D10: =A7+B8+C9 -> 512 | F10: 1. = select cell type + select next cell + next and last enter
F11: it will show cell address like =A7+B8+C9
A12: SUB: | F12: 2. you do also direcly | H12: "= 67+67+67" and enter
A13: 45
B14: 34
C15: 5 | D15: =A13-B14-C15 -> 6
A17: MUL:
A18: 6
B19: 7 | C19: 8 | D19: =A18*B19*C19 -> 336
A21: DIV:
A22: 90 | B22: 7 | C22: 3 | D22: =A22/B22/C22 -> 4.2857143
A24: Directly: | B24: =67+67+67 -> 201
A26: ADD | B26: 3 | C26: 3 | D26: 7 | E26: =B26+C26+D26 -> 13
F27: =8+8+7 -> 23

Sheet 4.Excel Ranges
O1: 46081
A3: 1. Select Cell
A5: 2. Select Multiple
A6: use cntrl key and select that
A7: and use enter key to move in that selected cells
A14: 3. From first row 1 to 10 select first using shift and select last row
A30: 4. from A1 to G10
A46: 5. ctrl+ shift + pg down arrow
A66: 6. for all rows select arrow on that row number
A67: 7. ctrl+shift+right arrow for rows
A85: 8. Name that ranges
B86: range1 | C86: 3 | D86: 45 | E86: 6
B87: range2 | C87: 7 | D87: 7 | E87: 7 | F87: =SUM(range1,range2) -> 75
C89: 2 | D89: 3

Sheet Sheet67

Sheet 5.Excel Fill
A2: 1.Copy | B2: 1 | C2: hello Smita | D2: 2
B3: 1 | C3: hello Smita
B4: 1 | C4: hello Smita
B5: 1 | C5: hello Smita
B6: 1 | C6: hello Smita
B7: 1 | C7: hello Smita
B8: 1 | C8: hello Smita
B9: you can drag from top to bottom either wise you can just double click on first cell
A12: 2.Sequence | B12: 11 | C12: Hi 101
B13: 22 | C13: Hi 102
B14: 33 | C14: Hi 103
B15: 44 | C15: Hi 104
B16: 55 | C16: Hi 105
B17: 66 | C17: Hi 106
B18: 77 | C18: Hi 107
B19: 88 | C19: Hi 108
B20: 99 | C20: Hi 109
B21: 110 | C21: Hi 110
B22: 121 | C22: Hi 111 | L22: x | M22: y | N22: P | O22: Q | P22: Total
L23: 4 | M23: 6 | P23: =L23+M23 -> 10
A24: 3.Date | B24: use ctrl + := for time | C24: 0.48819444 | L24: 5 | M24: 7 | P24: =L24+M24 -> 12
B25: use ctrl+ ; = for date | C25: 46083 | H25: 03/13/2026 | L25: 6 | M25: 8 | P25: =L25+M25 -> 14
C26: 46084 | H26: 03/13/2027 | L26: 7 | M26: 9 | P26: =L26+M26 -> 16
C27: 46085 | H27: 03/13/2028 | L27: 8 | M27: 10 | P27: =L27+M27 -> 18
C28: 46086 | H28: 03/13/2029
C29: 46087 | H29: 03/13/2030 | L29: for above case when I insert column head value then olny it will count without headerit is not calculate
B30: if you drag exact date format which you have in system then only it will work otherwise not
A32: 4. ADD
B33: 45 | C33: 34 | D33: =B33+C33 -> 79
B34: 54 | C34: 44 | D34: =B34+C34 -> 98
B35: 63 | C35: 54 | D35: =B35+C35 -> 117
B36: 72 | C36: 64 | D36: =B36+C36 -> 136
B37: 81 | C37: 74 | D37: =B37+C37 -> 155
B38: Now only add 1st row other for calculate use + icon select or double click on that
B40: Doble click - there should be value before the column | F40: 4 | G40: =E40+F40 -> 4 | H40: =F40+G40 -> 8
B41: If click on + then not work | D41: 5 | E41: 6 | H41: =F41+G41 -> 0

Sheet 6.References
A3: EXCEL Relative Reference:-You just perform addition of 1 row others will calculate by using + double click
B4: 45 | C4: 34 | D4: =B4+C4 -> 79 | Q4: 2222
B5: 54 | C5: 44 | D5: =B5+C5 -> 98
B6: 63 | C6: 54 | D6: =B6+C6 -> 117
B7: 72 | C7: 64 | D7: =B7+C7 -> 136
B8: 81 | C8: 74 | D8: =B8+C8 -> 155
A10: EXCEL Absolute Reference: In this column value will change for first operation but for second opretaion that should be constant use fn key + F4
D11: Percentage
C12: Sale | D12: 20
C13: Product List | D13: Price
C14: T-Shirt | D14: 200 | E14: =D14*(100-$D$12)/100 -> 160
C15: Tops | D15: 400 | E15: =D15*(100-$D$12)/100 -> 320
C17: otherwise use
A20: EXCEL Partial Reference : Depends on situation we have to apply lock on row or column not whole cell address as we performed in asolute reference we lock whole cell address
L23: product | M23: a | N23: Euro | O23: US Dollar | P23: Chinese Yuan
M24: 1 | N24: 1.26 | O24: 1.61 | P24: 1.62
L25: item 1 | M25: 56.5 | N25: =$M25*N$24 -> 71.19 | O25: =$M25*O$24 -> 90.965 | P25: =$M25*P$24 -> 91.53
L26: item 2 | M26: 57.5 | N26: =$M26*N$24 -> 72.45 | O26: =$M26*O$24 -> 92.575 | P26: =$M26*P$24 -> 93.15
L27: item 3 | M27: 58.5 | N27: =$M27*N$24 -> 73.71 | O27: =$M27*O$24 -> 94.185 | P27: =$M27*P$24 -> 94.77
L28: item 4 | M28: 59.5 | N28: =$M28*N$24 -> 74.97 | O28: =$M28*O$24 -> 95.795 | P28: =$M28*P$24 -> 96.39
L29: item 5 | M29: 60.5 | N29: =$M29*N$24 -> 76.23 | O29: =$M29*O$24 -> 97.405 | P29: =$M29*P$24 -> 98.01
L30: item 6 | M30: 61.5 | N30: =$M30*N$24 -> 77.49 | O30: =$M30*O$24 -> 99.015 | P30: =$M30*P$24 -> 99.63
L31: item 7 | M31: 62.5 | N31: =$M31*N$24 -> 78.75 | O31: =$M31*O$24 -> 100.625 | P31: =$M31*P$24 -> 101.25
L32: item 8 | M32: 63.5 | N32: =$M32*N$24 -> 80.01 | O32: =$M32*O$24 -> 102.235 | P32: =$M32*P$24 -> 102.87

Sheet 7.Parentheses
A1: =(10+5)+(2*4)+(4/2) -> 25
A2: 1.10+2*3 = In this first solve multiflication then addition here gives preference to * first like high order
A3: 2.(10+2)*3 -=HERE gives preferences to parentheses first it solve parentheses then outer layer operation perform
A4: 3.((10*2)+(10*2))+4 = here first inner parentheses solved under the outer parentheses then next operation performs.

Sheet 8.Format Numbers
A2: Format Types: | E2: Short Date | F2: 19452
E3: Long date | F3: 19452
A24: Payment Recipt | K24: 52 | M24: 46086
A25: Items | B25: Price | C25: Qty | D25: Total | K25: 46
A26: A | B26: 10 | C26: 2 | D26: =B26+C26 -> 12
A27: B | B27: 20 | C27: 3 | D27: =B27+C27 -> 23
A28: C | B28: 30 | C28: 4 | D28: =B28+C28 -> 34
A29: D | B29: 40 | C29: 5 | D29: =B29+C29 -> 45
A30: E | B30: 50 | C30: 6 | D30: =B30+C30 -> 56
A31: F | B31: 60 | C31: 7 | D31: =B31+C31 -> 67
A32: Total | B32: =SUM(D26:D31) -> 237 | C32: Discount | D32: 0.15
A33: Discount | B33: =B32*D32 -> 35.55
A34: Total Amount | B34: =B32-(B32*D32) -> 201.45

Sheet 9.Regional Settings

Sheet 10.Sort
A2: 1. Sort
A24: Name | F24: 1. First select A to Z from 25
A25: Beedrill
A26: Blastoise
A27: Bulbasaur
A28: Butterfree
A29: Caterpie
A30: Charizard
A31: Charmander
A32: Charmeleon
A33: Ivysaur
A34: Kakuna
A35: Metapod
A36: Pidgeotto
... A44: Weedle
A46: Total stats | F46: 2. Sort smallest to largest
A47: 195
A48: 195
A49: 205
A50: 205
A51: 251
A52: 253
A53: 309
A54: 314
A55: 318
A56: 349
A57: 395
A58: 395
... A66: 534
F67: 3. Sort with relative column
A68: Name | B68: Total stats
A69: Weedle | B69: 195
A70: Wartortle | B70: 405
A71: Venusaur | B71: 525
A72: Squirtle | B72: 314
A73: Rattata | B73: 253
A74: Raticate | B74: 413
A75: Pidgey | B75: 251
A76: Pidgeotto | B76: 349
A77: Pidgeotto | B77: 479
...

Sheet 11.Filter
A1: ID# | B1: Name | C1: Type 1 | D1: Type 2 | E1: Total | I1: 1
A2: 1 | B2: Bulbasaur | C2: Grass | D2: Poison | E2: 318 | N2: V | O2: Select range then apply fi;ter then that column shows arrow and dropdown and perform
A3: 2 | B3: Ivysaur | C3: Grass | D3: Poison | E3: 405
A4: 3 | B4: Venusaur | C4: Grass | D4: Poison | E4: 525
A5: 4 | B5: Charmander | C5: Fire | E5: 309
A6: 5 | B6: Charmeleon | C6: Fire | E6: 405
A7: 6 | B7: Charizard | C7: Fire | D7: Flying | E7: 534
A8: 7 | B8: Squirtle | C8: Water | E8: 314
A9: 8 | B9: Wartortle | C9: Water | E9: 405
A10: 9 | B10: Blastoise | C10: Water | E10: 530
A11: 10 | B11: Caterpie | C11: Bug | E11: 195
A12: 11 | B12: Metapod | C12: Bug | E12: 205
A13: 12 | B13: Butterfree | C13: Bug | D13: Flying | E13: 395
A14: 13 | B14: Weedle | C14: Bug | D14: Poisoin | E14: 195
A15: 14 | B15: Kakuna | C15: Bug | D15: Poison | E15: 205
A16: 15 | B16: Beedrill | C16: Bug | D16: Poison | E16: 395
A17: 16 | B17: Pidgey | C17: Normal | D17: Flying | E17: 251
A18: 17 | B18: Pidgeotto | C18: Normal | D18: Flying | E18: 349
A19: 18 | B19: Pidgeot | C19: Normal | D19: Flying | E19: 479
A20: 19 | B20: Rattata | C20: Normal | E20: 253
A21: 20 | B21: Raticate | C21: Normal | E21: 413
I22: 2 | Q22: Text filter
I45: 3 | S45: Number filter
I74: 4 | P74: clear filter

Sheet 12.Filter Assignment
A3: 1. Sorting a Dataset by Multiple Columns
A5: Objective: Sort a dataset of employees by their department, then by their salary in descending order.
A7: Create a table with columns such as Employee Name, Department, Salary, Date of Joining.
A8: Sort the table first by the Department column (alphabetically), and then by Salary in descending order within each department.
A10: Employee Table
A11: Employee Name | B11: Department | C11: Salary | D11: DOJ
A12: Vikram Mehta | B12: Operations | C12: 50000 | D12: 43207
A13: Sandeep Gupta | B13: Accounts | C13: 45000 | D13: 44104
A14: Anjali Nair | B14: Accounts | C14: 42000 | D14: 44430
A15: Rohit Verma | B15: Sales | C15: 40000 | D15: 44967
A16: Pooja Singh | B16: Research and Development | C16: 38000 | D16: 44903
A17: Rahul Patil | B17: Human Resources | C17: 35000 | D17: 44760
A18: Neha Joshi | B18: Accounts | C18: 32000 | D18: 44361
A19: Priya Deshmukh | B19: Finance | C19: 30000 | D19: 43895
A20: Sneha Kulkarni | B20: Human Resources | C20: 28000 | D20: 43794
A21: Amit Sharma | B21: Human Resources | C21: 25000 | D21: 44208
A23: 2. Filtering Data Based on Multiple Criteria
A25: Objective: Filter a sales data table to only show sales transactions above a certain value and from specific regions.
A27: Create a dataset with columns such as Sales ID, Date, Region, Sales Amount.
A28: Use the Filter feature to display only rows where the Sales Amount is greater than $500 and the Region is either "North" or "West."
F29: $1500 here
A30: Sales Table
A31: Sales ID | B31: Date | C31: Region | D31: Sales Amount
A32: S001 | B32: 45296 | C32: North | D32: 15000
A33: S002 | B33: 45303 | C33: South | D33: 22000
A34: S003 | B34: 45309 | C34: East | D34: 18000 | G34: filter in sheet 15
A35: S004 | B35: 45316 | C35: West | D35: 25000
A36: S005 | B36: 45324 | C36: Central | D36: 30000
A37: S006 | B37: 45332 | C37: North | D37: 27000
A38: S007 | B38: 45340 | C38: North | D38: 21000
A39: S008 | B39: 45348 | C39: South-East | D39: 35000
A40: S009 | B40: 45356 | C40: West | D40: 40000
A41: S010 | B41: 45363 | C41: International | D41: 32000
A43: Objective: Use the Advanced Filter to extract unique records from a list of transactions.
A45: Create a table with columns such as Transaction ID, Product Name, and Customer ID.
A46: Use the Advanced Filter to display only unique Product Names without duplications.
A48: Transaction Table
A49: Transaction ID | B49: Product Name | C49: Customer ID
A50: T001 | B50: Laptop | C50: C001
A51: T002 | B51: Mouse | C51: C002 | E51: will learn in conidtional formating
...

Sheet 12.Filter Assignment1
A1: Sales Table
A2: Sales ID | B2: Date | C2: Region | D2: Sales Amount
A3: S001 | B3: 45296 | C3: North | D3: 15000
A4: S002 | B4: 45303 | C4: South | D4: 22000
A5: S003 | B5: 45309 | C5: East | D5: 18000
A6: S004 | B6: 45316 | C6: West | D6: 25000
A7: S005 | B7: 45324 | C7: Central | D7: 30000
A8: S006 | B8: 45332 | C8: North | D8: 27000
A9: S007 | B9: 45340 | C9: North | D9: 21000
A10: S008 | B10: 45348 | C10: South-East | D10: 35000
A11: S009 | B11: 45356 | C11: West | D11: 40000
A12: S010 | B12: 45363 | C12: International | D12: 32000

Sheet 13.Excel Tables
A2: Tables allow for options such as: Sort & Filter Formatting AutoFilling
A9: Name | B9: Type 1 | C9: Type 2 | D9: HP | E9: Attack | F9: Defense | G9: Total | K9: 1.select cell inside table and ctrl+A then whole table will get selected
A10: Abra | B10: Psychic | D10: 25 | E10: 20 | F10: 15 | G10: =SUM(Table6[[#This Row],[HP]],Table6[[#This Row],[Attack]],Table6[[#This Row],[Defense]]) -> 60 | K10: 2.ctrl + T
A11: Bellsprout | B11: Grass | C11: Poison | D11: 50 | E11: 75 | F11: 35 | G11: =SUM(Table6[[#This Row],[HP]],Table6[[#This Row],[Attack]],Table6[[#This Row],[Defense]]) -> 160 | K11: sort and filter
A12: Geodude | B12: Rock | C12: Ground | D12: 40 | E12: 80 | F12: 100 | G12: =SUM(Table6[[#This Row],[HP]],Table6[[#This Row],[Attack]],Table6[[#This Row],[Defense]]) -> 220
A13: Slowpoke | B13: Water | C13: Psychic | D13: 90 | E13: 65 | F13: 65 | G13: =SUM(Table6[[#This Row],[HP]],Table6[[#This Row],[Attack]],Table6[[#This Row],[Defense]]) -> 220 | K13: autofill
A14: Magnemite | B14: Electric | C14: Steel | D14: 25 | E14: 35 | F14: 70 | G14: =SUM(Table6[[#This Row],[HP]],Table6[[#This Row],[Attack]],Table6[[#This Row],[Defense]]) -> 130
A15: Farfetch'd | B15: Normal | C15: Flying | D15: 52 | E15: 65 | F15: 55 | G15: =SUM(Table6[[#This Row],[HP]],Table6[[#This Row],[Attack]],Table6[[#This Row],[Defense]]) -> 172
A16: Total | G16: =SUBTOTAL(109,Table6[Total]) -> 962
K19: Formatting - Table design

Sheet 14.ECF - Color Scale
A1: Name | B1: Type 1 | C1: Speed
A2: Bulbasaur | B2: Grass | C2: 45
A3: Ivysaur | B3: Grass | C3: 60
A4: Venusaur | B4: Grass | C4: 80
A5: Charmander | B5: Fire | C5: 50
A6: Charmeleon | B6: Fire | C6: 80
A7: Charizard | B7: Fire | C7: 100
A8: Squirtle | B8: Water | C8: 43
A9: Wartortle | B9: Water | C9: 58
M10: Conditional Formatting
M12: Conditional formatting is used to change the appearance of cells in a range based on your specified conditions.
M14: The conditions are rules based on specified numerical values or matching text.
A15: 1) Color Scale:
A16: Name | B16: Type 1 | C16: Speed | M16: Built in condtional formatting:
A17: Bulbasaur | B17: Grass | C17: 45
A18: Ivysaur | B18: Grass | C18: 60
A19: Venusaur | B19: Grass | C19: 80
A20: Charmander | B20: Fire | C20: 65
A21: Charmeleon | B21: Fire | C21: 80
A22: Charizard | B22: Fire | C22: 100
A23: Squirtle | B23: Water | C23: 43
A24: Wartortle | B24: Water | C24: 58
M43: color Scale:
M70: New Rule:

Sheet 15.ECF - Excel Highlight Cell R
I2: You can apply multiple rules on dataset by prcoessing same procdure to apply rule 2 times
I3: you can check that using Manage Rule which rule is applied
U11: 5. Multiple rule
A12: 1.Greater Than | K12: 2. Less Than:
A13: Name | B13: Type 1 | C13: HP | D13: Attack | E13: Defense | F13: Sp. Atk | G13: Sp. Def | H13: Speed | K13: Name | L13: Type 1 | M13: HP | N13: Attack | O13: Defense | P13: Sp. Atk | Q13: Sp. Def | R13: Speed | U13: Name | V13: Type 1 | W13: HP | X13: Attack | Y13: Defense | Z13: Sp. Atk | AA13: Sp. Def | AB13: Speed
A14: Magikarp | B14: Water | C14: 20 | D14: 10 | E14: 55 | F14: 15 | G14: 20 | H14: 80 | K14: Magikarp | L14: Water | M14: 20 | N14: 10 | O14: 55 | P14: 15 | Q14: 20 | R14: 80 | U14: Magikarp | V14: Water | W14: 20 | X14: 10 | Y14: 55 | Z14: 15 | AA14: 20 | AB14: 80
A15: Gyarados | B15: Water | C15: 95 | D15: 125 | E15: 79 | F15: 60 | G15: 100 | H15: 81 | K15: Gyarados | L15: Water | M15: 95 | N15: 125 | O15: 79 | P15: 60 | Q15: 100 | R15: 81 | U15: Gyarados | V15: Water | W15: 95 | X15: 125 | Y15: 79 | Z15: 60 | AA15: 100 | AB15: 81
A16: Lapras | B16: Water | C16: 130 | D16: 85 | E16: 80 | F16: 85 | G16: 95 | H16: 60 | K16: Lapras | L16: Water | M16: 130 | N16: 85 | O16: 80 | P16: 85 | Q16: 95 | R16: 60 | U16: Lapras | V16: Water | W16: 130 | X16: 85 | Y16: 80 | Z16: 85 | AA16: 95 | AB16: 60
A17: Ditto | B17: Normal | C17: 48 | D17: 48 | E17: 48 | F17: 48 | G17: 48 | H17: 48 | K17: Ditto | L17: Normal | M17: 48 | N17: 48 | O17: 48 | P17: 48 | Q17: 48 | R17: 48 | U17: Ditto | V17: Normal | W17: 48 | X17: 48 | Y17: 48 | Z17: 48 | AA17: 48 | AB17: 48
A18: Eevee | B18: Normal | C18: 55 | D18: 55 | E18: 50 | F18: 45 | G18: 65 | H18: 55 | K18: Eevee | L18: Normal | M18: 55 | N18: 55 | O18: 50 | P18: 45 | Q18: 65 | R18: 55 | U18: Eevee | V18: Normal | W18: 55 | X18: 55 | Y18: 50 | Z18: 45 | AA18: 65 | AB18: 55
A19: Vaporeon | B19: Water | C19: 130 | D19: 65 | E19: 60 | F19: 110 | G19: 95 | H19: 65 | K19: Vaporeon | L19: Water | M19: 130 | N19: 65 | O19: 60 | P19: 110 | Q19: 95 | R19: 65 | U19: Vaporeon | V19: Water | W19: 130 | X19: 65 | Y19: 60 | Z19: 110 | AA19: 95 | AB19: 65
A20: Jolteon | B20: Electric | C20: 65 | D20: 65 | E20: 60 | F20: 110 | G20: 95 | H20: 130 | K20: Jolteon | L20: Electric | M20: 65 | N20: 65 | O20: 60 | P20: 110 | Q20: 95 | R20: 130 | U20: Jolteon | V20: Electric | W20: 65 | X20: 65 | Y20: 60 | Z20: 110 | AA20: 95 | AB20: 130
A23: 3.Between | K23: 4.Equal To
A24: Name | B24: Type 1 | C24: HP | D24: Attack | E24: Defense | F24: Sp. Atk | G24: Sp. Def | H24: Speed | K24: Name | L24: Type 1 | M24: HP | N24: Attack | O24: Defense | P24: Sp. Atk | Q24: Sp. Def | R24: Speed
A25: Magikarp | B25: Water | C25: 20 | D25: 10 | E25: 55 | F25: 15 | G25: 20 | H25: 80 | K25: Magikarp | L25: Water | M25: 20 | N25: 10 | O25: 55 | P25: 15 | Q25: 20 | R25: 80
A26: Gyarados | B26: Water | C26: 95 | D26: 125 | E26: 79 | F26: 60 | G26: 100 | H26: 81 | K26: Gyarados | L26: Water | M26: 95 | N26: 125 | O26: 79 | P26: 60 | Q26: 100 | R26: 81
A27: Lapras | B27: Water | C27: 130 | D27: 85 | E27: 80 | F27: 85 | G27: 95 | H27: 60 | K27: Lapras | L27: Water | M27: 130 | N27: 85 | O27: 80 | P27: 85 | Q27: 95 | R27: 60
A28: Ditto | B28: Normal | C28: 48 | D28: 48 | E28: 48 | F28: 48 | G28: 48 | H28: 48 | K28: Ditto | L28: Normal | M28: 48 | N28: 48 | O28: 48 | P28: 48 | Q28: 48 | R28: 48
A29: Eevee | B29: Normal | C29: 55 | D29: 55 | E29: 50 | F29: 45 | G29: 65 | H29: 55 | K29: Eevee | L29: Normal | M29: 55 | N29: 55 | O29: 50 | P29: 45 | Q29: 65 | R29: 55
A30: Vaporeon | B30: Water | C30: 130 | D30: 65 | E30: 60 | F30: 110 | G30: 95 | H30: 65 | K30: Vaporeon | L30: Water | M30: 130 | N30: 65 | O30: 60 | P30: 110 | Q30: 95 | R30: 65
A31: Jolteon | B31: Electric | C31: 65 | D31: 65 | E31: 60 | F31: 110 | G31: 95 | H31: 130 | K31: Jolteon | L31: Electric | M31: 65 | N31: 65 | O31: 60 | P31: 110 | Q31: 95 | R31: 130
A33: 6.Not Between
A34: Name | B34: Type 1 | C34: HP | D34: Attack | E34: Defense | F34: Sp. Atk | G34: Sp. Def | H34: Speed
A35: Magikarp | B35: Water | C35: 20 | D35: 10 | E35: 55 | F35: 15 | G35: 20 | H35: 80
A36: Gyarados | B36: Water | C36: 95 | D36: 125 | E36: 79 | F36: 60 | G36: 100 | H36: 81
A37: Lapras | B37: Water | C37: 130 | D37: 85 | E37: 80 | F37: 85 | G37: 95 | H37: 60
A38: Ditto | B38: Normal | C38: 48 | D38: 48 | E38: 48 | F38: 48 | G38: 48 | H38: 48
A39: Eevee | B39: Normal | C39: 55 | D39: 55 | E39: 50 | F39: 45 | G39: 65 | H39: 55
A40: Vaporeon | B40: Water | C40: 130 | D40: 65 | E40: 60 | F40: 110 | G40: 95 | H40: 65
A41: Jolteon | B41: Electric | C41: 65 | D41: 65 | E41: 60 | F41: 110 | G41: 95 | H41: 130
A43: 7. Not Equal to
A44: Name | B44: Type 1 | C44: HP | D44: Attack | E44: Defense | F44: Sp. Atk | G44: Sp. Def | H44: Speed
A45: Magikarp | B45: Water | C45: 20 | D45: 10 | E45: 55 | F45: 15 | G45: 20 | H45: 80
A46: Gyarados | B46: Water | C46: 95 | D46: 125 | E46: 79 | F46: 60 | G46: 100 | H46: 81
A47: Lapras | B47: Water | C47: 130 | D47: 85 | E47: 80 | F47: 85 | G47: 95 | H47: 60
A48: Ditto | B48: Normal | C48: 48 | D48: 48 | E48: 48 | F48: 48 | G48: 48 | H48: 48
A49: Eevee | B49: Normal | C49: 55 | D49: 55 | E49: 50 | F49: 45 | G49: 65 | H49: 55
A50: Vaporeon | B50: Water | C50: 130 | D50: 65 | E50: 60 | F50: 110 | G50: 95 | H50: 65
A51: Jolteon | B51: Electric | C51: 65 | D51: 65 | E51: 60 | F51: 110 | G51: 95 | H51: 130
A53: 8.Grater than or equal to
...

Sheet 16.ECF- Text
A1: Employee Name | B1: Department | C1: Salary | D1: DOJ
A2: Vikram Mehta | B2: Operations | C2: 50000 | D2: 43207
A3: Sandeep Gupta | B3: Accounts | C3: 45000 | D3: 44104
A4: Anjali Nair | B4: Accounts | C4: 42000 | D4: 44430
A5: Rohit Verma | B5: Sales | C5: 40000 | D5: 44967
A6: Pooja Singh | B6: Research and Development | C6: 38000 | D6: 44903
A7: Rahul Patil | B7: Human Resources | C7: 35000 | D7: 44760
A8: Neha Joshi | B8: Accounts | C8: 32000 | D8: 44361
A9: Priya Deshmukh | B9: Finance | C9: 30000 | D9: 43895
A10: Sneha Kulkarni | B10: Human Resources | C10: 28000 | D10: 43794
A11: Amit Sharma | B11: Human Resources | C11: 25000 | D11: 44208
B12: Sales
B15: 1
A42: 1. Text that Contains:
A44: Employee Name | B44: Department | C44: Salary | D44: DOJ
A45: Vikram Mehta | B45: Operations | C45: 50000 | D45: 43207 | F45: 1.Select only Dept Column
A46: Sandeep Gupta | B46: Accounts | C46: 45000 | D46: 44104
A47: Anjali Nair | B47: Accounts | C47: 42000 | D47: 44430
A48: Rohit Verma | B48: Sales | C48: 40000 | D48: 44967
A49: Pooja Singh | B49: Research and Development | C49: 38000 | D49: 44903
A50: Rahul Patil | B50: Human Resources | C50: 35000 | D50: 44760
A51: Neha Joshi | B51: Accounts | C51: 32000 | D51: 44361
A52: Priya Deshmukh | B52: Finance | C52: 30000 | D52: 43895
A53: Sneha Kulkarni | B53: Human Resources | C53: 28000 | D53: 43794
A54: Amit Sharma | B54: Human Resources | C54: 25000 | D54: 44208
A56: 2. Other option get from New Rule
A84: 2. Not containing | F84: 3.Begining with | L84: 4.ending with
A85: Employee Name | B85: Department | C85: Salary | D85: DOJ | F85: Employee Name | G85: Department | H85: Salary | I85: DOJ | L85: Employee Name | M85: Department | N85: Salary | O85: DOJ
A86: Vikram Mehta | B86: Operations | C86: 50000 | D86: 43207 | F86: Vikram Mehta | G86: Operations | H86: 50000 | I86: 43207 | L86: Vikram Mehta | M86: Operations | N86: 50000 | O86: 43207
A87: Sandeep Gupta | B87: Accounts | C87: 45000 | D87: 44104 | F87: Sandeep Gupta | G87: Accounts | H87: 45000 | I87: 44104 | L87: Sandeep Gupta | M87: Accounts | N87: 45000 | O87: 44104
A88: Anjali Nair | B88: Accounts | C88: 42000 | D88: 44430 | F88: Anjali Nair | G88: Accounts | H88: 42000 | I88: 44430 | L88: Anjali Nair | M88: Accounts | N88: 42000 | O88: 44430
A89: Rohit Verma | B89: Sales | C89: 40000 | D89: 44967 | F89: Rohit Verma | G89: Sales | H89: 40000 | I89: 44967 | L89: Rohit Verma | M89: Sales | N89: 40000 | O89: 44967
A90: Pooja Singh | B90: Research and Development | C90: 38000 | D90: 44903 | F90: Pooja Singh | G90: Research and Development | H90: 38000 | I90: 44903 | L90: Pooja Singh | M90: Research and Development | N90: 38000 | O90: 44903
A91: Rahul Patil | B91: Human Resources | C91: 35000 | D91: 44760 | F91: Rahul Patil | G91: Human Resources | H91: 35000 | I91: 44760 | L91: Rahul Patil | M91: Human Resources | N91: 35000 | O91: 44760
A92: Neha Joshi | B92: Accounts | C92: 32000 | D92: 44361 | F92: Neha Joshi | G92: Accounts | H92: 32000 | I92: 44361 | L92: Neha Joshi | M92: Accounts | N92: 32000 | O92: 44361
A93: Priya Deshmukh | B93: Finance | C93: 30000 | D93: 43895 | F93: Priya Deshmukh | G93: Finance | H93: 30000 | I93: 43895 | L93: Priya Deshmukh | M93: Finance | N93: 30000 | O93: 43895
A94: Sneha Kulkarni | B94: Human Resources | C94: 28000 | D94: 43794 | F94: Sneha Kulkarni | G94: Human Resources | H94: 28000 | I94: 43794 | L94: Sneha Kulkarni | M94: Human Resources | N94: 28000 | O94: 43794
A95: Amit Sharma | B95: Human Resources | C95: 25000 | D95: 44208 | F95: Amit Sharma | G95: Human Resources | H95: 25000 | I95: 44208 | L95: Amit Sharma | M95: Human Resources | N95: 25000 | O95: 44208

Sheet 17.ECF- Date
A14: Name | B14: Type 1 | C14: Birthday | D14: Year
A15: Bulbasaur | B15: Grass | C15: 46080 | D15: 1996
A16: Charmander | B16: Fire | C16: 46080 | D16: 1996
A17: Squirtle | B17: Water | C17: 46080 | D17: 1996
A18: Chikorita | B18: Grass | C18: 46090 | D18: 1999
A19: Cyndaquil | B19: Fire | C19: 46091 | D19: 1999
A20: Totodile | B20: Water | C20: 46092 | D20: 1999
A21: Treecko | B21: Grass | C21: 46093 | D21: 2002
A22: Torchic | B22: regular | C22: 46094 | D22: 2002
A23: Mudkip | B23: Water | C23: 46095 | D23: 2002
A24: Turtwig | B24: Grass | C24: 46096 | D24: 2006
A25: Chimchar | B25: Fire | C25: 46097 | D25: 2006
A26: Piplup | B26: Water | C26: 46098 | D26: 2006
... A32: Froakie | B32: Water | C32: 46127 | D32: 2013
A34: You can same as from New Rule

Sheet 18.ECF Duplicate values
A2: 1. Duplicate Values
A4: Name | B4: Type 1 | C4: Speed
A5: Bulbasaur | B5: Grass | C5: 45
A6: Ivysaur | B6: Grass | C6: 60
A7: Venusaur | B7: Grass | C7: 80
A8: Charmander | B8: Fire | C8: 65
A9: Charmeleon | B9: Fire | C9: 80
A10: Charizard | B10: Fire | C10: 100
A11: Squirtle | B11: Water | C11: 43
A12: Wartortle | B12: Water | C12: 58
A13: Blastoise | B13: Water | C13: 78
A14: Caterpie | B14: Bug | C14: 45
A15: Metapod | B15: Bug | C15: 30
A16: Butterfree | B16: Bug | C16: 70
A19: 2. From New Rule
A42: unique values
A43: Name | B43: Type 1 | C43: Speed
A44: Bulbasaur | B44: Grass | C44: 45
A45: Ivysaur | B45: Grass | C45: 60
A46: Venusaur | B46: Grass | C46: 80
A47: Charmander | B47: Fire | C47: 65
A48: Charmeleon | B48: Fire | C48: 80
A49: Charizard | B49: Fire | C49: 100
A50: Squirtle | B50: Water | C50: 43
A51: Wartortle | B51: Water | C51: 58
A52: Blastoise | B52: Water | C52: 78
A53: Caterpie | B53: Bug | C53: 45
A54: Metapod | B54: Bug | C54: 30
A55: Butterfree | B55: Bug | C55: 70
A59: Name | B59: Type 1 | C59: Speed
A60: Bulbasaur | B60: Grass | C60: 45
A61: Ivysaur | B61: Grass | C61: 60
A62: Venusaur | B62: Grass | C62: 80
A63: Charmander | B63: Fire | C63: 65
A64: Charmeleon | B64: Fire | C64: 80
A65: Charizard | B65: Fire | C65: 100
A66: Squirtle | B66: Water | C66: 43
A67: Wartortle | B67: Water | C67: 58
A68: Blastoise | B68: Water | C68: 78
A69: Caterpie | B69: Bug | C69: 45
...

Sheet 19.ECF- TopBottom Rules
A2: Name | B2: Type 1 | C2: Speed
A3: Bulbasaur | B3: Grass | C3: 45
A4: Ivysaur | B4: Grass | C4: 60 | E4: 1. Top 10 and bottom 10
A5: Venusaur | B5: Grass | C5: 80
A6: Charmander | B6: Fire | C6: 65
A7: Charmeleon | B7: Fire | C7: 80
A8: Charizard | B8: Fire | C8: 100
A9: Squirtle | B9: Water | C9: 43
A10: Wartortle | B10: Water | C10: 58
A11: Blastoise | B11: Water | C11: 78
A12: Caterpie | B12: Bug | C12: 45
A13: Metapod | B13: Bug | C13: 30
A14: Butterfree | B14: Bug | C14: 70
A15: Weedle | B15: Bug | C15: 50
A16: Kakuna | B16: Bug | C16: 35
... A32: Nidorina | B32: Poison | C32: 56
A35: Name | B35: Type 1 | C35: Speed
A36: Bulbasaur | B36: Grass | C36: 45 | M36: you can do also
A37: Ivysaur | B37: Grass | C37: 60
A38: Venusaur | B38: Grass | C38: 80
A39: Charmander | B39: Fire | C39: 65
A40: Charmeleon | B40: Fire | C40: 80 | F40: 2. top 10 % and bottom 10 %
A41: Charizard | B41: Fire | C41: 100
A42: Squirtle | B42: Water | C42: 43
A43: Wartortle | B43: Water | C43: 58
A44: Blastoise | B44: Water | C44: 78
A45: Caterpie | B45: Bug | C45: 45
A46: Metapod | B46: Bug | C46: 30
A47: Butterfree | B47: Bug | C47: 70
A48: Weedle | B48: Bug | C48: 50
A49: Kakuna | B49: Bug | C49: 35
A50: Beedrill | B50: Bug | C50: 75
A51: Pidgey | B51: Normal | C51: 45
A52: Pidgeotto | B52: Normal | C52: 71
... A65: Nidorina | B65: Poison | C65: 56
A67: Name | B67: Type 1 | C67: Speed
A68: Bulbasaur | B68: Grass | C68: 45 | E68: 3. Above avg and below avg
A69: Ivysaur | B69: Grass | C69: 60
A70: Venusaur | B70: Grass | C70: 80
A71: Charmander | B71: Fire | C71: 65
...

Sheet Sheet24

Sheet ECF Data Bar
A3: 1. New Rule: Data bar
A30: Name | B30: Type 1 | C30: Speed
A31: Bulbasaur | B31: Grass | C31: 45
A32: Ivysaur | B32: Grass | C32: 60
A33: Venusaur | B33: Grass | C33: 80
A34: Charmander | B34: Fire | C34: 65
A35: Charmeleon | B35: Fire | C35: 80
A36: Charizard | B36: Fire | C36: 100
A37: Squirtle | B37: Water | C37: 10
A38: Wartortle | B38: Water | C38: 58
A39: Blastoise | B39: Water | C39: 78
A40: Caterpie | B40: Bug | C40: 45
A41: Metapod | B41: Bug | C41: -110
A42: Butterfree | B42: Bug | C42: 70

Sheet ECF ICON SET
A4: 90 | C4: 5
A5: 60 | C5: 3
A6: 30 | C6: 1
A9: 1
A34: 2

Sheet Excel Functions -IF
A3: Function 1: IF
A12: Name | B12: Type 1 | C12: Total | D12: More than 500 Total Stats | E12: check ="grass" | F12: check leass than 500
A13: Bulbasaur | B13: Grass | C13: 318 | D13: =IF(C13>500,"yes","no") -> no | E13: =IF(B13="grass","true", "false") -> true | F13: =IF(C13<500,"True","False") -> True
A14: Ivysaur | B14: Grass | C14: 405 | D14: =IF(C14>500,"yes","no") -> no | E14: =IF(B14="grass","true", "false") -> true | F14: =IF(C14<500,"True","False") -> True
A15: Venusaur | B15: Grass | C15: 525 | D15: =IF(C15>500,"yes","no") -> yes | E15: =IF(B15="grass","true", "false") -> true | F15: =IF(C15<500,"True","False") -> False
A16: Charmander | B16: Fire | C16: 309 | D16: =IF(C16>500,"yes","no") -> no | E16: =IF(B16="grass","true", "false") -> false | F16: =IF(C16<500,"True","False") -> True
A17: Charmeleon | B17: Fire | C17: 405 | D17: =IF(C17>500,"yes","no") -> no | E17: =IF(B17="grass","true", "false") -> false | F17: =IF(C17<500,"True","False") -> True
A18: Charizard | B18: Fire | C18: 534 | D18: =IF(C18>500,"yes","no") -> yes | E18: =IF(B18="grass","true", "false") -> false | F18: =IF(C18<500,"True","False") -> False
A19: Squirtle | B19: Water | C19: 314 | D19: =IF(C19>500,"yes","no") -> no | E19: =IF(B19="grass","true", "false") -> false | F19: =IF(C19<500,"True","False") -> True
A20: Wartortle | B20: Water | C20: 405 | D20: =IF(C20>500,"yes","no") -> no | E20: =IF(B20="grass","true", "false") -> false | F20: =IF(C20<500,"True","False") -> True
A21: Blastoise | B21: Water | C21: 530 | D21: =IF(C21>500,"yes","no") -> yes | E21: =IF(B21="grass","true", "false") -> false | F21: =IF(C21<500,"True","False") -> False

Sheet IF Assignment
A1: IF
E8: Order ID | F8: Date Time | G8: Customer | H8: Item | I8: Price | J8: Tax | K8: Status
E9: A001 | F9: 44884.599 | G9: Ross | H9: Pizza | I9: 6.99 | J9: =IF(Table7[[#This Row],[Price]]>$N$25,Table7[[#This Row],[Price]]*1.1,Table7[[#This Row],[Price]]) -> 7.689 | K9: =IF(Table7[[#This Row],[Price]]>$N$25,"Including Tax","") -> Including Tax
E10: A002 | F10: 44884.599 | G10: Ross | H10: Drinks | I10: 2.5 | J10: =IF(Table7[[#This Row],[Price]]>$N$25,Table7[[#This Row],[Price]]*1.1,Table7[[#This Row],[Price]]) -> 2.5 | K10: =IF(Table7[[#This Row],[Price]]>$N$25,"Including Tax","")
E11: A003 | F11: 44884.599 | G11: Ross | H11: Pizza | I11: 8.99 | J11: =IF(Table7[[#This Row],[Price]]>$N$25,Table7[[#This Row],[Price]]*1.1,Table7[[#This Row],[Price]]) -> 9.889 | K11: =IF(Table7[[#This Row],[Price]]>$N$25,"Including Tax","") -> Including Tax
E12: A004 | F12: 44884.619 | G12: Joey | H12: Pizza | I12: 12.99 | J12: =IF(Table7[[#This Row],[Price]]>$N$25,Table7[[#This Row],[Price]]*1.1,Table7[[#This Row],[Price]]) -> 14.289 | K12: =IF(Table7[[#This Row],[Price]]>$N$25,"Including Tax","") -> Including Tax
E13: A005 | F13: 44884.64 | G13: Ross | H13: Burger | I13: 5.99 | J13: =IF(Table7[[#This Row],[Price]]>$N$25,Table7[[#This Row],[Price]]*1.1,Table7[[#This Row],[Price]]) -> 6.589 | K13: =IF(Table7[[#This Row],[Price]]>$N$25,"Including Tax","") -> Including Tax
E14: A006 | F14: 44884.64 | G14: Joey | H14: Sub Sandwich | I14: 5.99 | J14: =IF(Table7[[#This Row],[Price]]>$N$25,Table7[[#This Row],[Price]]*1.1,Table7[[#This Row],[Price]]) -> 6.589 | K14: =IF(Table7[[#This Row],[Price]]>$N$25,"Including Tax","") -> Including Tax
E15: A007 | F15: 44884.64 | G15: Joey | H15: Sub Sandwich | I15: 5.99 | J15: =IF(Table7[[#This Row],[Price]]>$N$25,Table7[[#This Row],[Price]]*1.1,Table7[[#This Row],[Price]]) -> 6.589 | K15: =IF(Table7[[#This Row],[Price]]>$N$25,"Including Tax","") -> Including Tax
E16: A008 | F16: 44884.641 | G16: Joey | H16: Sub Sandwich | I16: 5.99 | J16: =IF(Table7[[#This Row],[Price]]>$N$25,Table7[[#This Row],[Price]]*1.1,Table7[[#This Row],[Price]]) -> 6.589 | K16: =IF(Table7[[#This Row],[Price]]>$N$25,"Including Tax","") -> Including Tax
E17: A009 | F17: 44884.641 | G17: Joey | H17: Sub Sandwich | I17: 5.99 | J17: =IF(Table7[[#This Row],[Price]]>$N$25,Table7[[#This Row],[Price]]*1.1,Table7[[#This Row],[Price]]) -> 6.589 | K17: =IF(Table7[[#This Row],[Price]]>$N$25,"Including Tax","") -> Including Tax
E18: A010 | F18: 44884.649 | G18: Monica | H18: Hot Dog | I18: 7.99 | J18: =IF(Table7[[#This Row],[Price]]>$N$25,Table7[[#This Row],[Price]]*1.1,Table7[[#This Row],[Price]]) -> 8.789 | K18: =IF(Table7[[#This Row],[Price]]>$N$25,"Including Tax","") -> Including Tax
E19: A011 | F19: 44884.65 | G19: Monica | H19: Drinks | I19: 2.99 | J19: =IF(Table7[[#This Row],[Price]]>$N$25,Table7[[#This Row],[Price]]*1.1,Table7[[#This Row],[Price]]) -> 2.99 | K19: =IF(Table7[[#This Row],[Price]]>$N$25,"Including Tax","")
E20: A012 | F20: 44884.656 | G20: Gunther | H20: Pizza | I20: 12.99 | J20: =IF(Table7[[#This Row],[Price]]>$N$25,Table7[[#This Row],[Price]]*1.1,Table7[[#This Row],[Price]]) -> 14.289 | K20: =IF(Table7[[#This Row],[Price]]>$N$25,"Including Tax","") -> Including Tax
... E24: A016 | F24: 44884.665 | G24: Rachel | H24: Pizza | I24: 12.99 | J24: =IF(Table7[[#This Row],[Price]]>$N$25,Table7[[#This Row],[Price]]*1.1,Table7[[#This Row],[Price]]) -> 14.289 | K24: =IF(Table7[[#This Row],[Price]]>$N$25,"Including Tax","") -> Including Tax
E25: A017 | F25: 44884.665 | G25: Rachel | H25: Pizza | I25: 9.99 | J25: =IF(Table7[[#This Row],[Price]]>$N$25,Table7[[#This Row],[Price]]*1.1,Table7[[#This Row],[Price]]) -> 10.989 | K25: =IF(Table7[[#This Row],[Price]]>$N$25,"Including Tax","") -> Including Tax | N25: 5
E26: A018 | F26: 44884.665 | G26: Rachel | H26: Pizza | I26: 9.99 | J26: =IF(Table7[[#This Row],[Price]]>$N$25,Table7[[#This Row],[Price]]*1.1,Table7[[#This Row],[Price]]) -> 10.989 | K26: =IF(Table7[[#This Row],[Price]]>$N$25,"Including Tax","") -> Including Tax
E27: A019 | F27: 44884.665 | G27: Rachel | H27: Drinks | I27: 2.99 | J27: =IF(Table7[[#This Row],[Price]]>$N$25,Table7[[#This Row],[Price]]*1.1,Table7[[#This Row],[Price]]) -> 2.99 | K27: =IF(Table7[[#This Row],[Price]]>$N$25,"Including Tax","")
E28: A020 | F28: 44884.684 | G28: Chandler | H28: Tea | I28: 1.99 | J28: =IF(Table7[[#This Row],[Price]]>$N$25,Table7[[#This Row],[Price]]*1.1,Table7[[#This Row],[Price]]) -> 1.99 | K28: =IF(Table7[[#This Row],[Price]]>$N$25,"Including Tax","")
E29: A021 | F29: 44884.698 | G29: Phoebe | H29: Pizza | I29: 7.99 | J29: =IF(Table7[[#This Row],[Price]]>$N$25,Table7[[#This Row],[Price]]*1.1,Table7[[#This Row],[Price]]) -> 8.789 | K29: =IF(Table7[[#This Row],[Price]]>$N$25,"Including Tax","") -> Including Tax
E30: A022 | F30: 44884.698 | G30: Phoebe | H30: Burger | I30: 5.99 | J30: =IF(Table7[[#This Row],[Price]]>$N$25,Table7[[#This Row],[Price]]*1.1,Table7[[#This Row],[Price]]) -> 6.589 | K30: =IF(Table7[[#This Row],[Price]]>$N$25,"Including Tax","") -> Including Tax
E31: A023 | F31: 44884.699 | G31: Phoebe | H31: Drinks | I31: 2.99 | J31: =IF(Table7[[#This Row],[Price]]>$N$25,Table7[[#This Row],[Price]]*1.1,Table7[[#This Row],[Price]]) -> 2.99 | K31: =IF(Table7[[#This Row],[Price]]>$N$25,"Including Tax","")

Sheet IFS 
A1: Name | B1: Type 1 | C1: Speed | D1: Speed Category
A2: Bulbasaur | B2: Grass | C2: 45 | D2: {=_xlfn.IFS(C2>90,"Fast",C2>50,"normal",C2<=50,"Slow")} -> Slow | F2: "=IFS(C2>90,"Fast",C2>50,"normal",C2<=50,"Slow")"
A3: Ivysaur | B3: Grass | C3: 60 | D3: {=_xlfn.IFS(C3>90,"Fast",C3>50,"normal",C3<=50,"Slow")} -> normal
A4: Venusaur | B4: Grass | C4: 80 | D4: {=_xlfn.IFS(C4>90,"Fast",C4>50,"normal",C4<=50,"Slow")} -> normal
A5: Charmander | B5: Fire | C5: 50 | D5: {=_xlfn.IFS(C5>90,"Fast",C5>50,"normal",C5<=50,"Slow")} -> Slow
A6: Charmeleon | B6: Fire | C6: 80 | D6: {=_xlfn.IFS(C6>90,"Fast",C6>50,"normal",C6<=50,"Slow")} -> normal
A7: Charizard | B7: Fire | C7: 100 | D7: {=_xlfn.IFS(C7>90,"Fast",C7>50,"normal",C7<=50,"Slow")} -> Fast
A8: Squirtle | B8: Water | C8: 43 | D8: {=_xlfn.IFS(C8>90,"Fast",C8>50,"normal",C8<=50,"Slow")} -> Slow
A9: Wartortle | B9: Water | C9: 58 | D9: {=_xlfn.IFS(C9>90,"Fast",C9>50,"normal",C9<=50,"Slow")} -> normal
A10: Blastoise | B10: Water | C10: 78 | D10: {=_xlfn.IFS(C10>90,"Fast",C10>50,"normal",C10<=50,"Slow")} -> normal
D11: {=_xlfn.IFS(C11>90,"Fast",C11>50,"normal",C11<=50,"Slow")} -> Slow
A12: IFS
A13: Student Name | B13: Subject | C13: Marks | E13: Marks Category
A14: Rahul | B14: Maths | C14: 45 | E14: {=_xlfn.IFS(C14>75,"Excellent",C14>60,"Good",C14>50,"AVG",C14<=50,"Fail")} -> Fail | F14: "=IFS(C14>75,"Excellent",C14>60,"Good",C14>50,"AVG",C14<=50,"Fail")"
A15: Priya | B15: Science | C15: 60 | E15: {=_xlfn.IFS(C15>75,"Excellent",C15>60,"Good",C15>50,"AVG",C15<=50,"Fail")} -> AVG
A16: Amit | B16: English | C16: 80 | E16: {=_xlfn.IFS(C16>75,"Excellent",C16>60,"Good",C16>50,"AVG",C16<=50,"Fail")} -> Excellent
A17: Neha | B17: Maths | C17: 50 | E17: {=_xlfn.IFS(C17>75,"Excellent",C17>60,"Good",C17>50,"AVG",C17<=50,"Fail")} -> Fail
A18: Rohan | B18: Science | C18: 90 | E18: {=_xlfn.IFS(C18>75,"Excellent",C18>60,"Good",C18>50,"AVG",C18<=50,"Fail")} -> Excellent

Sheet SUMIF
A2: Name | B2: Type 1 | C2: Total
A3: Bulbasaur | B3: Grass | C3: 318 | E3: Type | F3: Total Sum
A4: Ivysaur | B4: Grass | C4: 405 | E4: Grass | F4: =SUMIF(B3:B11,E4,C3:C11) -> 1248 | H4: "=SUMIF(B3:B11,E4,C3:C11)"
A5: Venusaur | B5: Grass | C5: 525 | E5: Fire | F5: =SUMIF(B4:B12,E5,C4:C12) -> 1248
A6: Charmander | B6: Fire | C6: 309 | E6: Water | F6: =SUMIF(B5:B12,E6,C5:C12) -> 1249
A7: Charmeleon | B7: Fire | C7: 405
A8: Charizard | B8: Fire | C8: 534
A9: Squirtle | B9: Water | C9: 314
A10: Wartortle | B10: Water | C10: 405
A11: Blastoise | B11: Water | C11: 530
A13: SUMIF
A15: Student Name | B15: Subject | C15: Marks | E15: Subjects | F15: Total
A16: Rahul | B16: Maths | C16: 45 | E16: Maths | F16: =SUMIF(B16:B25,E16,C16:C25) -> 95 | H16: "=SUMIF(B16:B25,E16,C16:C25)"
A17: Priya | B17: Science | C17: 60 | E17: Science | F17: =SUMIF(B17:B26,E17,C17:C26) -> 150
A18: Amit | B18: English | C18: 80 | E18: English | F18: =SUMIF(B18:B27,E18,C18:C27) -> 80
A19: Neha | B19: Maths | C19: 50 | E19: Maths | F19: =SUMIF(B19:B28,E19,C19:C28) -> 50
A20: Rohan | B20: Science | C20: 90 | E20: Science | F20: =SUMIF(B20:B29,E20,C20:C29) -> 90

Sheet SUMIFS
A1: Name | B1: Type 1 | C1: Total
A2: Bulbasaur | B2: Grass | C2: 318
A3: Ivysaur | B3: Grass | C3: 405 | E3: =SUMIFS(C2:C10,B2:B10,"grass",C2:C10,">400") -> 930
A4: Venusaur | B4: Grass | C4: 525
A5: Charmander | B5: Fire | C5: 309
A6: Charmeleon | B6: Fire | C6: 405
A7: Charizard | B7: Fire | C7: 534
A8: Squirtle | B8: Water | C8: 314
A9: Wartortle | B9: Water | C9: 405
A10: Blastoise | B10: Water | C10: 530
A14: Date | B14: Region | C14: Product | D14: Sales Rep | E14: Units Sold | F14: Revenue ($)
A15: 45660 | B15: East | C15: Laptop | D15: Alice | E15: 5 | F15: 4000 | H15: 1 | I15: =SUMIF(C15:C23,"Laptop",F15:F23) -> 12800 | J15: "=SUMIF(C15:C23,"Laptop",F15:F23)"
A16: 45662 | B16: West | C16: Printer | D16: Bob | E16: 3 | F16: 900 | H16: 2 | I16: =SUMIFS(E15:E23,D15:D23,"Alice",B15:B23,"East") -> 9 | J16: "=SUMIFS(E15:E23,D15:D23,"Alice",B15:B23,"East")"
A17: 45664 | B17: East | C17: Laptop | D17: Alice | E17: 4 | F17: 3200 | H17: 3 | I17: =SUMIFS(F15:F23,C15:C23,"Printer",B15:B23,"East") -> 1500 | J17: "=SUMIFS(F15:F23,C15:C23,"Printer",B15:B23,"East")"
A18: 45667 | B18: East | C18: Monitor | D18: Charlie | E18: 6 | F18: 1800 | H18: 4 | I18: =SUMIFS(F15:F23,A15:A23,">=03-01-2025",A15:A23,"<=15-01-2025",D15:D23,"charlie") -> 1800 | J18: "=SUMIFS(F15:F23,A15:A23,">=03-01-2025",A15:A23,"<=15-01-2025",D15:D23,"charlie")"
A19: 45672 | B19: South | C19: Laptop | D19: Bob | E19: 2 | F19: 1600 | H19: 5 | I19: =SUMIF(C15:C23,"Monitor",E15:E23) -> 9 | J19: "=SUMIF(C15:C23,"Monitor",E15:E23)"
A20: 45708 | B20: West | C20: Monitor | D20: Alice | E20: 3 | F20: 900 | H20: 6 | I20: =SUMIFS(F15:F23,D15:D23,"Bob",B15:B23,"West") -> 4100 | J20: "=sumifs(F15:F23,D15:D23,"Bob",B15:B23,"West")"
A21: 45710 | B21: East | C21: Printer | D21: Charlie | E21: 5 | F21: 1500 | H21: 7 | I21: =SUMIFS(F15:F23,C15:C23,"Laptop",B15:B23,"South",D15:D23,"Charlie") -> 800 | J21: "=SUMIFS(F15:F23,C15:C23,"Laptop",B15:B23,"South",D15:D23,"Charlie")" | L21: Laptop | M21: B15:B23 | N21: South | O21: D15:D23 | P21: Charlie)
A22: 45713 | B22: South | C22: Laptop | D22: Charlie | E22: 1 | F22: 800 | H22: 8 | I22: =SUMIF(B15:B23,"East",E15:E23) -> 20 | J22: "=sumif(B15:B23,"East",E15:E23)"
A23: 45716 | B23: West | C23: Laptop | D23: Bob | E23: 4 | F23: 3200 | H23: 9 | I23: =SUMIFS(F15:F23,C15:C23,"Monitor",D15:D23,"Alice") -> 900 | J23: "=sumifs(F15:F23,C15:C23,"Monitor",D15:D23,"Alice")"
H24: 10 | I24: =SUMIF(A15:A23,">15-01-2025",F15:F23) -> 6400 | J24: "=SUMIF(A15:A23,">15-01-2025",F15:F23)"

Sheet AND
A1: Name | B1: Type 1 | C1: Speed | D1: Fire Type AND more than 70 Speed
A2: Bulbasaur | B2: Grass | C2: 45 | D2: =AND(B2="fire",C2>70) -> FALSE
A3: Ivysaur | B3: Grass | C3: 60 | D3: =AND(B3="fire",C3>70) -> FALSE
A4: Venusaur | B4: Grass | C4: 80 | D4: =AND(B4="fire",C4>70) -> FALSE
A5: Charmander | B5: Fire | C5: 65 | D5: =AND(B5="fire",C5>70) -> FALSE
A6: Charmeleon | B6: Fire | C6: 80 | D6: =AND(B6="fire",C6>70) -> TRUE
A7: Charizard | B7: Fire | C7: 100 | D7: =AND(B7="fire",C7>70) -> TRUE
A8: Squirtle | B8: Water | C8: 43 | D8: =AND(B8="fire",C8>70) -> FALSE
A9: Wartortle | B9: Water | C9: 58 | D9: =AND(B9="fire",C9>70) -> FALSE
A10: Blastoise | B10: Water | C10: 78 | D10: =AND(B10="fire",C10>70) -> FALSE
A14: Name | B14: Type 1 | C14: Speed | D14: Fire Type AND more than 70 Speed
A15: Bulbasaur | B15: Grass | C15: 45 | D15: =AND(B15="Fire",C15>70) -> FALSE | E15: "=AND(B15="Fire",C15>70)"
A16: Ivysaur | B16: Grass | C16: 60 | D16: =AND(B16="Fire",C16>70) -> FALSE
A17: Venusaur | B17: Grass | C17: 80 | D17: =AND(B17="Fire",C17>70) -> FALSE
A18: Charmander | B18: Fire | C18: 65 | D18: =AND(B18="Fire",C18>70) -> FALSE
A19: Charmeleon | B19: Fire | C19: 80 | D19: =AND(B19="Fire",C19>70) -> TRUE
A20: Charizard | B20: Fire | C20: 100 | D20: =AND(B20="Fire",C20>70) -> TRUE
A21: Squirtle | B21: Water | C21: 43 | D21: =AND(B21="Fire",C21>70) -> FALSE
A22: Wartortle | B22: Water | C22: 58 | D22: =AND(B22="Fire",C22>70) -> FALSE
A23: Blastoise | B23: Water | C23: 78 | D23: =AND(B23="Fire",C23>70) -> FALSE

Sheet Average
A1: Trainer | B1: Pokeball | C1: Great Ball | D1: Ultraball | E1: Master Ball | F1: Average
A2: Iva | B2: 10 | C2: 4 | D2: 1 | E2: 1 | F2: =AVERAGE(B2:E2) -> 4
A3: Liam | B3: 12 | C3: 3 | D3: 0 | E3: 1 | F3: =AVERAGE(B3:E3) -> 4
A4: Jenny | B4: 15 | C4: 1 | D4: 3 | E4: 1 | F4: =AVERAGE(B4:E4) -> 5
A5: Iben | B5: 4 | C5: 2 | D5: 6 | E5: 0 | F5: =AVERAGE(B5:E5) -> 3
A6: Adora | B6: 10 | C6: 4 | D6: 1 | E6: 1 | F6: =AVERAGE(B6:E6) -> 4
A7: Kasper | B7: 9 | C7: 2 | D7: 1 | E7: 0 | F7: =AVERAGE(B7:E7) -> 3
A13: Trainer | B13: Pokeball | C13: Great Ball | D13: Ultraball | E13: Master Ball | F13: Average
A14: Iva | B14: 10 | C14: 4 | D14: 1 | E14: 1 | F14: =AVERAGE(B14:E14) -> 4 | H14: "=AVERAGE(B14:E14)"
A15: Liam | B15: 12 | C15: 3 | D15: 0 | E15: 1 | F15: =AVERAGE(B15:E15) -> 4
A16: Jenny | B16: 15 | C16: 1 | D16: 3 | E16: 1 | F16: =AVERAGE(B16:E16) -> 5
A17: Iben | B17: 4 | C17: 2 | D17: 6 | E17: 0 | F17: =AVERAGE(B17:E17) -> 3
A18: Adora | B18: 10 | C18: 4 | D18: 1 | E18: 1 | F18: =AVERAGE(B18:E18) -> 4
A19: Kasper | B19: 9 | C19: 2 | D19: 1 | E19: 0 | F19: =AVERAGE(B19:E19) -> 3

Sheet AVERAGEIF
A3: Name | B3: Type 1 | C3: Speed
A4: Bulbasaur | B4: Grass | C4: 45 | E4: Type | F4: Average Speed
A5: Ivysaur | B5: Grass | C5: 60 | E5: Grass | F5: =AVERAGEIF(B4:B12,"Grass",C4:C12) -> 61.666667
A6: Venusaur | B6: Grass | C6: 80 | E6: Fire | F6: =AVERAGEIF(B4:B12,B7,C4:C12) -> 81.666667
A7: Charmander | B7: Fire | C7: 65 | E7: Water | F7: =AVERAGEIF(B4:B12,B10,C4:C12) -> 59.666667
A8: Charmeleon | B8: Fire | C8: 80 | H8: =AVERAGEIF(B4:B12,Grass" | I8: C4:C12)"
A9: Charizard | B9: Fire | C9: 100
A10: Squirtle | B10: Water | C10: 43
A11: Wartortle | B11: Water | C11: 58
A12: Blastoise | B12: Water | C12: 78

Sheet AVERAGEIFS
A4: Name | B4: Type 1 | C4: Defense | D4: Generation
A5: Bulbasaur | B5: Grass | C5: 49 | D5: 1 | F5: Type | G5: Gen. | H5: Average Defense
A6: Ivysaur | B6: Grass | C6: 63 | D6: 1 | F6: Grass | G6: 1 | H6: =AVERAGEIFS(C5:C16,B5:B16,"Grass",D5:D16,"1") -> 65
A7: Venusaur | B7: Grass | C7: 83 | D7: 1 | F7: Fire | G7: 1 | H7: =AVERAGEIFS(C5:C16,B5:B16,"Fire",D5:D16,"1") -> 59.666667
A8: Charmander | B8: Fire | C8: 43 | D8: 1 | F8: Grass | G8: 2 | H8: =AVERAGEIFS(C5:C16,B5:B16,"Grass",D5:D16,"2") -> 81.666667
A9: Charmeleon | B9: Fire | C9: 58 | D9: 1 | F9: Fire | G9: 2 | H9: =AVERAGEIFS(C5:C16,B5:B16,"Fire",D5:D16,"2") -> 59.666667 | J9: "=AVERAGEIFS(C5:C16,B5:B16,"Fire",D5:D16,"2")"
A10: Charizard | B10: Fire | C10: 78 | D10: 1
A11: Chikorita | B11: Grass | C11: 65 | D11: 2
A12: Bayleef | B12: Grass | C12: 80 | D12: 2
A13: Meganium | B13: Grass | C13: 100 | D13: 2
A14: Cyndaquil | B14: Fire | C14: 43 | D14: 2
A15: Quilava | B15: Fire | C15: 58 | D15: 2
A16: Typhlosion | B16: Fire | C16: 78 | D16: 2

Sheet Count All fuctions
A2: 1 | B2: COUNT | C2: This works on only number dataset | F2: If you want to add count on anothersheet 37 then you have to active formula
A3: 2 | B3: COUNTA | C3: This works on both numbers and text | F3: 1. Goto sheet 37 type =counta(
A4: 3 | B4: COUNTBLANK | C4: This counts how many blank fields are there | F4: 2. come here sheet 36 select range and type" )" and make enter
A5: 4 | B5: COUNTIF | C5: This counts on condition1 | F5: 3. see count on sheet 37
A6: 5 | B6: COUNTIFS | C6: This counts of different different conditions
A9: NETLEAP TRAINING CENTER, Gangapur Road
A10: Student ID | B10: Student Name | C10: Course Name | D10: Gender | E10: Phone Number | F10: Admission Date | G10: PAID
A11: S101 | B11: Rahul Patil | C11: cloud | D11: Male | E11: 9876543210 | F11: 46034 | G11: No
A12: S102 | B12: Sneha Joshi | C12: Cyber Crime | D12: Female | E12: 9123456780 | F12: 46037 | G12: YES
A13: S103 | B13: Smita Amrutkar | C13: Data Analytics | D13: Female | E13: 8978776565 | F13: 46080 | G13: NO
A14: S104 | B14: Tushar Amrutkar | C14: Full Stack Developer | D14: Male | E14: 7787788888 | F14: 46032 | G14: NO
A15: S105 | B15: Anuja | C15: Python | D15: Female | E15: 9876543210 | F15: 46024 | G15: YES
A16: S106 | B16: Sohan | C16: Advance Excel | D16: Male | F16: 46025 | G16: NO
A17: S107 | B17: Zohan | C17: C | D17: Male | E17: 9876543210 | F17: 46026 | G17: YES
A18: S108 | B18: Mahisha | C18: C++ | D18: Female | E18: 6765654345 | F18: 46027 | G18: YES
A19: S109 | B19: Kayra | C19: Digital Markjeting | D19: Female | E19: 9876543210 | F19: 46028 | G19: YES
A20: S110 | B20: Tejas | C20: Data Analytics | D20: Male | E20: 8978776565 | F20: 46029 | G20: NO
A21: S111 | B21: Utkarsh | C21: Data Science | D21: Male | E21: 9876543210 | F21: 46030 | G21: NO
A22: S112 | B22: Neha | C22: Big Data | D22: Female | F22: 46031 | G22: YES
A23: S113 | B23: Tina | C23: Cloud | D23: Female | E23: 9876543210 | F23: 46032 | G23: NO
A24: S114 | B24: Jit | C24: Cloud | D24: Male | E24: 2345678765 | F24: 46033 | G24: NO
A25: S115 | B25: Hema | C25: Advance Excel | D25: Female | E25: 8978776565 | F25: 46034 | G25: YES

Sheet RESULT OF COUNT
B5: 1 | C5: COUNT | D5: =COUNT('Count All fuctions'!E11:E25) -> 13 | E5: This count on number but blank it is not count
B6: 2 | C6: COUNTA | D6: =COUNTA('Count All fuctions'!C11:C25) -> 15
B7: 3 | C7: COUNTBLANK | D7: =COUNTBLANK('Count All fuctions'!E11:E25) -> 2
B8: 4 | C8: COUNTIF | D8: =COUNTIF('Count All fuctions'!C11:C25,'Count All fuctions'!C11) -> 3 | E8: "Data analtcis how many students are doing"
B9: 5 | C9: COUNTIFS | D9: =COUNTIFS('Count All fuctions'!C11:C25,'Count All fuctions'!C11,'Count All fuctions'!G11:G25,'Count All fuctions'!G11,'Count All fuctions'!D11:D25,'Count All fuctions'!D11) -> 2 | E9: "Data analytics paid fee and "Male Candidates"
D10: =COUNTIFS('Count All fuctions'!C11:C25,'Count All fuctions'!C24,'Count All fuctions'!G11:G25,'Count All fuctions'!G24) -> 3 | E10: "Cloud course not paid candidates"
D11: =COUNTIF('Count All fuctions'!G11:G25,'Count All fuctions'!G11) -> 8 | E11: "paid candidates"

Sheet TEXT Oprations
P1: Name | Q1: Surname | R1: Full Name
P2: Smita | Q2: Amrutkar | R2: hello
A3: SR NO | B3: Functions: | C3: Syntax: | N3: Example: | O3: =LEFT(P2,2) -> Sm
A4: 1 | B4: LEFT
A8: 2 | B8: Right | O8: =RIGHT(Q2,4) -> tkar
A12: 3 | B12: UPPER | O12: =UPPER(P2) -> SMITA
A16: 4 | B16: LOWER | O16: =LOWER(Q2) -> amrutkar
A20: 5 | B20: CONCAT | O20: =_xlfn.CONCAT(P2," ",Q2) -> Smita Amrutkar
A23: 6 | B23: PROPER
S24: =PROPER(R2) -> Hello
A28: 7 | B28: TRIM
O29: Smita Hi | P29: =TRIM(O29) -> Smita Hi

Sheet AND OR XOR
A1: Name | B1: Type 1 | C1: Defense | D1: Water Type OR more than 60 Defense | E1: FireTYpe XOR more than 50 Defence | F1: Grass Type AND mor than 60 | G1: Formulas: | H1: AND
A2: Bulbasaur | B2: Grass | C2: 49 | D2: =OR(B2="water",C2>60) -> FALSE | E2: =_xlfn.XOR(B2="fire",C2>50) -> FALSE | F2: =AND(B2="Grass",C2>60) -> FALSE | G2: "=OR(B2="water",C2>60)" | H2: T | I2: T | J2: T
A3: Ivysaur | B3: Grass | C3: 63 | D3: =OR(B3="water",C3>60) -> TRUE | E3: =_xlfn.XOR(B3="fire",C3>50) -> TRUE | F3: =AND(B3="Grass",C3>60) -> TRUE | G3: "=XOR(B2="fire",C2>50)" | H3: F | I3: F | J3: F
A4: Venusaur | B4: Grass | C4: 83 | D4: =OR(B4="water",C4>60) -> TRUE | E4: =_xlfn.XOR(B4="fire",C4>50) -> TRUE | F4: =AND(B4="Grass",C4>60) -> TRUE | G4: "=AND(B2="Grass",C2>60) | H4: T | I4: F | J4: F
A5: Charmander | B5: Fire | C5: 43 | D5: =OR(B5="water",C5>60) -> FALSE | E5: =_xlfn.XOR(B5="fire",C5>50) -> TRUE | F5: =AND(B5="Grass",C5>60) -> FALSE | H5: F | I5: T | J5: F
A6: Charmeleon | B6: Fire | C6: 58 | D6: =OR(B6="water",C6>60) -> FALSE | E6: =_xlfn.XOR(B6="fire",C6>50) -> FALSE | F6: =AND(B6="Grass",C6>60) -> FALSE
A7: Charizard | B7: Fire | C7: 78 | D7: =OR(B7="water",C7>60) -> TRUE | E7: =_xlfn.XOR(B7="fire",C7>50) -> FALSE | F7: =AND(B7="Grass",C7>60) -> FALSE | H7: OR
A8: Squirtle | B8: Water | C8: 65 | D8: =OR(B8="water",C8>60) -> TRUE | E8: =_xlfn.XOR(B8="fire",C8>50) -> TRUE | F8: =AND(B8="Grass",C8>60) -> FALSE | H8: T | I8: T | J8: T
A9: Wartortle | B9: Water | C9: 50 | D9: =OR(B9="water",C9>60) -> TRUE | E9: =_xlfn.XOR(B9="fire",C9>50) -> FALSE | F9: =AND(B9="Grass",C9>60) -> FALSE | H9: F | I9: F | J9: F
A10: Blastoise | B10: Water | C10: 100 | D10: =OR(B10="water",C10>60) -> TRUE | E10: =_xlfn.XOR(B10="fire",C10>50) -> TRUE | F10: =AND(B10="Grass",C10>60) -> FALSE | H10: T | I10: F | J10: T
H11: F | I11: T | J11: T
H13: XOR
H14: T | I14: T | J14: F
H15: F | I15: F | J15: F
H16: T | I16: F | J16: T
H17: F | I17: T | J17: T

Sheet Sheet48
D68: No thanks, click

Sheet MATH Oprations
A3: 1 | B3: MIN | R3: Total stats | T3: =MIN(R4:R23) -> 200
R4: 305
R5: 510
R6: 490
A7: 2 | B7: MAX | R7: 335 | T7: =MAX(R4:R23) -> 1000
R8: 465
R9: 475
R10: 525 | T10: =RAND() -> 0.95943873 | U10: =INT(RAND()*20) -> 10
A11: 3 | B11: RAND | R11: 385
R12: 420
R13: 349
R14: 253
R15: 1000 | T15: =MEDIAN(R4:R23) -> 429
A16: 4 | B16: MEDIAN | R16: 310
R17: 475
R18: 505
R19: 455
A20: 5 | B20: MODE | R20: 405 | T20: =MODE(R4:R23) -> 475
R21: 438
R22: 310
R23: 200

Sheet Sheet45
A1: Student ID | B1: Student Name | C1: Course Name | D1: Gender | E1: Phone Number | F1: Admission Date | G1: PAID
A2: S101 | B2: Rahul Patil | C2: cloud | D2: Male | E2: 9876543210 | F2: 46034 | G2: No
A3: S102 | B3: Sneha Joshi | C3: Cyber Crime | D3: Female | E3: 9123456780 | F3: 46037 | G3: YES | J3: anuja | K3: =VLOOKUP($J$3,$B$2:$G$16,Q3,FALSE) -> Python | L3: =VLOOKUP(K3,C2:H16,2,FALSE) -> Female | M3: =VLOOKUP(L3,D2:I16,2,FALSE) -> 9123456780 | N3: =VLOOKUP(M3,E2:J16,2,FALSE) -> 46037 | O3: =VLOOKUP(N3,F2:K16,2,FALSE) -> YES | Q3: 2
A4: S103 | B4: Smita Amrutkar | C4: Data Analytics | D4: Female | E4: 8978776565 | F4: 46080 | G4: NO | K4: =VLOOKUP($J$3,$B$2:$G$16,Q4,FALSE) -> Female | Q4: 3
A5: S104 | B5: Tushar Amrutkar | C5: Full Stack Developer | D5: Male | E5: 7787788888 | F5: 46032 | G5: NO | K5: =VLOOKUP($J$3,$B$2:$G$16,Q5,FALSE) -> 9876543210 | Q5: 4
A6: S105 | B6: Anuja | C6: Python | D6: Female | E6: 9876543210 | F6: 46024 | G6: YES | K6: =VLOOKUP($J$3,$B$2:$G$16,Q6,FALSE) -> 46024 | Q6: 5
A7: S106 | B7: Sohan | C7: Advance Excel | D7: Male | F7: 46025 | G7: NO | K7: =VLOOKUP($J$3,$B$2:$G$16,Q7,FALSE) -> YES | Q7: 6
A8: S107 | B8: Zohan | C8: C | D8: Male | E8: 9876543210 | F8: 46026 | G8: YES
A9: S108 | B9: Mahisha | C9: C++ | D9: Female | E9: 6765654345 | F9: 46027 | G9: YES
A10: S109 | B10: Kayra | C10: Digital Markjeting | D10: Female | E10: 9876543210 | F10: 46028 | G10: YES
A11: S110 | B11: Tejas | C11: Data Analytics | D11: Male | E11: 8978776565 | F11: 46029 | G11: NO
A12: S111 | B12: Utkarsh | C12: Data Science | D12: Male | E12: 9876543210 | F12: 46030 | G12: NO
A13: S112 | B13: Neha | C13: Big Data | D13: Female | F13: 46031 | G13: YES
A14: S113 | B14: Tina | C14: Cloud | D14: Female | E14: 9876543210 | F14: 46032 | G14: NO
A15: S114 | B15: Jit | C15: Cloud | D15: Male | E15: 2345678765 | F15: 46033 | G15: NO
A16: S115 | B16: Hema | C16: Advance Excel | D16: Female | E16: 8978776565 | F16: 46034 | G16: YES | J16: if you want rowise data:" =VLOOKUP($J$3,$B$2:$G$16,Q4,FALSE)"

Sheet VLOOKUP
A2: Student ID | B2: Student Name | C2: Course Name | D2: Gender | E2: Phone Number | F2: Admission Date | G2: PAID
A3: S101 | B3: Rahul Patil | C3: cloud | D3: Male | E3: 9876543210 | F3: 46034 | G3: No | H3: Jit | I3: =VLOOKUP(H3,B3:G17,5,FALSE) -> 46033 | J3: "=VLOOKUP(H3,B3:G17,5,FALSE)"
A4: S102 | B4: Sneha Joshi | C4: Cyber Crime | D4: Female | E4: 9123456780 | F4: 46037 | G4: YES
A5: S103 | B5: Smita Amrutkar | C5: Data Analytics | D5: Female | E5: 8978776565 | F5: 46080 | G5: NO
A6: S104 | B6: Tushar Amrutkar | C6: Full Stack Developer | D6: Male | E6: 7787788888 | F6: 46032 | G6: NO
A7: S105 | B7: Anuja | C7: Python | D7: Female | E7: 9876543210 | F7: 46024 | G7: YES | H7: S101 | I7: =VLOOKUP(H7,A3:G17,4,FALSE) -> Male
A8: S106 | B8: Sohan | C8: Advance Excel | D8: Male | F8: 46025 | G8: NO | H8: S102 | I8: =VLOOKUP(H8,A4:G18,4,FALSE) -> Female
A9: S107 | B9: Zohan | C9: C | D9: Male | E9: 9876543210 | F9: 46026 | G9: YES | H9: S103 | I9: =VLOOKUP(H9,A5:G19,4,FALSE) -> Female
A10: S108 | B10: Mahisha | C10: C++ | D10: Female | E10: 6765654345 | F10: 46027 | G10: YES | H10: S104 | I10: =VLOOKUP(H10,A6:G20,4,FALSE) -> Male
A11: S109 | B11: Kayra | C11: Digital Markjeting | D11: Female | E11: 9876543210 | F11: 46028 | G11: YES | H11: S105 | I11: =VLOOKUP(H11,A7:G21,4,FALSE) -> Female
A12: S110 | B12: Tejas | C12: Data Analytics | D12: Male | E12: 8978776565 | F12: 46029 | G12: NO | H12: S106 | I12: =VLOOKUP(H12,A8:G22,4,FALSE) -> Male
A13: S111 | B13: Utkarsh | C13: Data Science | D13: Male | E13: 9876543210 | F13: 46030 | G13: NO | H13: S107 | I13: =VLOOKUP(H13,A9:G23,4,FALSE) -> Male
A14: S112 | B14: Neha | C14: Big Data | D14: Female | F14: 46031 | G14: YES | H14: S108 | I14: =VLOOKUP(H14,A10:G24,4,FALSE) -> Female
A15: S113 | B15: Tina | C15: Cloud | D15: Female | E15: 9876543210 | F15: 46032 | G15: NO | H15: S109 | I15: =VLOOKUP(H15,A11:G25,4,FALSE) -> Female
A16: S114 | B16: Jit | C16: Cloud | D16: Male | E16: 2345678765 | F16: 46033 | G16: NO | H16: S110 | I16: =VLOOKUP(H16,A12:G26,4,FALSE) -> Male
A17: S115 | B17: Hema | C17: Advance Excel | D17: Female | E17: 8978776565 | F17: 46034 | G17: YES | H17: S111 | I17: =VLOOKUP(H17,A13:G27,4,FALSE) -> Male
B20: The VLOOKUP function is a premade function in Excel, which allows searches across columns.
A24: Syntax:
B27: 1.lookup_value | C27: any empty cell select
B28: 2.table_array | C28: looup valu varun pude.konavarun kay kaadayche tithun puthd selectkarne full table forward way
B29: 3.col_index_num | C29: kay kadayche tyacha column from 1 st colu until that count
B30: 4.range_lookup | C30: exact macth or not select true or false

Sheet VLOOKUP using condition
A2: Student ID | B2: Student Name | C2: Course Name | D2: Gender | E2: Phone Number | F2: Admission Date | G2: PAID
A3: S101 | B3: Rahul Patil | C3: cloud | D3: Male | E3: 9876543210 | F3: 46034 | G3: No | I3: VLOOKUP using conditional formatting
A4: S102 | B4: Sneha Joshi | C4: Cyber Crime | D4: Female | E4: 9123456780 | F4: 46037 | G4: YES
A5: S103 | B5: Smita Amrutkar | C5: Data Analytics | D5: Female | E5: 8978776565 | F5: 46080 | G5: NO
A6: S104 | B6: Tushar Amrutkar | C6: Full Stack Developer | D6: Male | E6: 7787788888 | F6: 46032 | G6: NO
A7: S105 | B7: Anuja | C7: Python | D7: Female | E7: 9876543210 | F7: 46024 | G7: YES
A8: S106 | B8: Sohan | C8: Advance Excel | D8: Male | F8: 46025 | G8: NO
A9: S107 | B9: Zohan | C9: C | D9: Male | E9: 9876543210 | F9: 46026 | G9: YES
A10: S108 | B10: Mahisha | C10: C++ | D10: Female | E10: 6765654345 | F10: 46027 | G10: YES
A11: S109 | B11: Kayra | C11: Digital Markjeting | D11: Female | E11: 9876543210 | F11: 46028 | G11: YES
A12: S110 | B12: Tejas | C12: Data Analytics | D12: Male | E12: 8978776565 | F12: 46029 | G12: NO
A13: S111 | B13: Utkarsh | C13: Data Science | D13: Male | E13: 9876543210 | F13: 46030 | G13: NO
A14: S112 | B14: Neha | C14: Big Data | D14: Female | F14: 46031 | G14: YES
A15: S113 | B15: Tina | C15: Cloud | D15: Female | E15: 9876543210 | F15: 46032 | G15: NO
A16: S114 | B16: Jit | C16: Cloud | D16: Male | E16: 2345678765 | F16: 46033 | G16: NO
A17: S115 | B17: Hema | C17: Advance Excel | D17: Female | E17: 8978776565 | F17: 46034 | G17: YES
C22: S114
C23: =VLOOKUP(C22,A3:G17,7,FALSE) -> NO
B25: 1. step 1 add vlookup formula
B26: 2. select table array and go to New Rule and add formula like select first id = result cell that empty cell
B27: 3. remove $ sign

Sheet pvt
H2: Months (Admission Date) | I2: (All)
A3: Row Labels | B3: Sum of PAID Amount | D3: Row Labels | E3: Sum of Pending Amount | H3: Days (Admission Date) | I3: (All)
A4: Advance Excel | B4: 64000 | D4: Ankita | E4: 0
A5: Big Data | B5: 14000 | D5: Avishka | E5: 5000 | H5: Row Labels | I5: Count of Admission Date
A6: C++ | B6: 14000 | D6: Hema | E6: 5000 | H6: Advance Excel | I6: 3
A7: Cyber Crime | B7: 28000 | D7: Kayra | E7: 0 | H7: Big Data | I7: 1
A8: Data Analytics | B8: 30000 | D8: Neha | E8: 9000 | H8: C++ | I8: 1
A9: Digital Markjeting | B9: 28000 | D9: Pallavi | E9: 0 | H9: Cyber Crime | I9: 1
A10: Python | B10: 14000 | D10: Prachi | E10: 9000 | H10: Data Analytics | I10: 2
A11: Grand Total | B11: 192000 | D11: Smita Amrutkar | E11: 24000 | H11: Digital Markjeting | I11: 1
D12: Sneha OK | E12: 24000 | H12: Python | I12: 1
D13: Sohan | E13: 0 | H13: Grand Total | I13: 10
D14: Grand Total | E14: 76000

Sheet smitaa pivot
A3: Row Labels | B3: Sum of Pending Amount
A4: Advance Excel | B4: 27000
A5: C | B5: 0
A6: Cloud | B6: 45000
A7: Data Analytics | B7: 0
A8: Full Stack Developer | B8: 28000
A9: Grand Total | B9: 100000
A18: Steps:
A19: 1 | B19: Create Main Data
